<?xml version="1.0" ?>
<!-- =================================================================================== -->
<!-- |    This document was autogenerated by xacro from /home/skleff/.virtualenvs/croco_v2/lib/python3.8/site-packages/robot_properties_kuka/robot_properties_kuka/xacro/iiwa_ft_sensor_ball.urdf.xacro | -->
<!-- |    EDITING THIS FILE BY HAND IS NOT RECOMMENDED                                 | -->
<!-- =================================================================================== -->
<robot name="KUKAiiwa14" xmlns:xacro="http://www.ros.org/wiki/xacro">
  <mujoco>
    <compiler 
    meshdir="../meshes/kuka" 
    balanceinertia="false" 
    discardvisual="true"
    convexhull="false" />
  </mujoco>
  <material name="Black">
    <color rgba="0.0 0.0 0.0 1.0"/>
  </material>
  <material name="Blue">
    <color rgba="0.0 0.0 0.8 1.0"/>
  </material>
  <material name="Green">
    <color rgba="0.0 0.8 0.0 0.5"/>
  </material>
  <material name="Grey">
    <color rgba="0.4 0.4 0.4 1.0"/>
  </material>
  <material name="Orange">
    <color rgba="1.0 0.4235294117647059 0.0392156862745098 1.0"/>
  </material>
  <material name="Brown">
    <color rgba="0.8705882352941177 0.8117647058823529 0.7647058823529411 1.0"/>
  </material>
  <material name="Red">
    <color rgba="0.8 0.0 0.0 1.0"/>
  </material>
  <material name="White">
    <color rgba="1.0 1.0 1.0 1.0"/>
  </material>
  <!-- Fix to world just for testing -->


  <link name="world"/>


  <joint name="world_to_pusher_tip_goal" type="fixed">
    <parent link="world"/>
    <child link="pusher_tip_goal"/>
      <origin rpy="-3.14159 0 3.14159" xyz=".6 .2 .05"/>
  </joint>


  <link name="pusher_tip_goal" >


    <visual>
      <geometry>
        <sphere radius="0.02" />
      </geometry>
      <material name="Green"/>
    </visual>
    </link>



  <!--joint between WORLD and BASE-->
  <joint name="A0" type="fixed">
    <origin rpy="0 0 0" xyz="0 0 0"/>
    <parent link="world"/>
    <child link="iiwa_base"/>
  </joint>
  <!-- BASE -->
  <link name="iiwa_base">
    <inertial>
      <origin rpy="0 0 0" xyz="0 0 0"/>
      <mass value="5"/>
      <inertia ixx="0.05" ixy="0" ixz="0" iyy="0.06" iyz="0" izz="0.03"/>
    </inertial>
    <visual>
      <origin rpy="0 0 0" xyz="0 0 0"/>
      <geometry>
        <mesh filename="package://meshes/kuka/iiwa_base.stl"/>
      </geometry>
      <material name="Grey"/>
    </visual>
    <collision>
      <origin rpy="0 0 0" xyz="0 0 0"/>
      <geometry>
        <mesh filename="package://meshes/kuka/iiwa_base.stl"/>
      </geometry>
      <material name="Grey"/>
    </collision>
    <self_collision_checking>
      <origin rpy="0 0 0" xyz="0 0 0"/>
      <geometry>
        <capsule length="0.25" radius="0.15"/>
      </geometry>
    </self_collision_checking>
  </link>
  <!-- joint between base and link1 -->
  <joint name="A1" type="revolute">
    <origin rpy="0.0 0.0 0.0" xyz="0.00000 0.00000 0.15750"/>
    <parent link="iiwa_base"/>
    <child link="L1"/>
    <axis xyz="0 0 1"/>
    <limit effort="320" lower="-2.96706" upper="2.96706" velocity="1.48353"/>
    <!-- <safety_controller soft_lower_limit="${-168 * PI / 180}"
                          soft_upper_limit="${168 * PI / 180}"
                          k_position="${safety_controller_k_pos}"
                          k_velocity="${safety_controller_k_vel}"/> 
      <dynamics damping="${joint_damping}"/> -->
  </joint>
  <!-- LINK 1-->
  <link name="L1">
    <inertial>
      <origin xyz="0.00000 0.00000 0.00000"/>
      <mass value="3.94781"/>
      <inertia ixx="0.00455" ixy="0.00000" ixz="-0.00000" iyy="0.00454" iyz="-0.00001" izz="0.00029"/>
    </inertial>
    <visual>
      <origin rpy="0 0 0" xyz="0 0 0"/>
      <geometry>
        <mesh filename="package://meshes/kuka/iiwa_link_1.stl"/>
      </geometry>
      <material name="Orange"/>
    </visual>
    <collision>
      <origin rpy="0 0 0" xyz="0 0 0"/>
      <geometry>
        <mesh filename="package://meshes/kuka/iiwa_link_1.stl"/>
      </geometry>
      <material name="Orange"/>
    </collision>
  </link>
  <!-- joint between link1 and link2 -->
  <joint name="A2" type="revolute">
    <origin rpy="2.3561944901923457 -1.5707962635746238 2.3561944901923457" xyz="0.00000 0.00000 0.20250"/>
    <parent link="L1"/>
    <child link="L2"/>
    <axis xyz="0 0 1"/>
    <limit effort="320" lower="-2.0944" upper="2.0944" velocity="1.48353"/>
    <!-- <safety_controller soft_lower_limit="${-118 * PI / 180}"
                          soft_upper_limit="${118 * PI / 180}"
                          k_position="${safety_controller_k_pos}"
                          k_velocity="${safety_controller_k_vel}"/> 
      <dynamics damping="${joint_damping}"/> -->
  </joint>
  <!-- LINK 2-->
  <link name="L2">
    <inertial>
      <origin rpy="0 0 0" xyz="0.0003 0.059 0.042"/>
      <mass value="4.50275"/>
      <inertia ixx="0.00032" ixy="0" ixz="0" iyy="0.00010" iyz="0" izz="0.00042"/>
    </inertial>
    <visual>
      <origin rpy="0 0 0" xyz="0 0 0"/>
      <geometry>
        <mesh filename="package://meshes/kuka/iiwa_link_2.stl"/>
      </geometry>
      <material name="Orange"/>
    </visual>
    <collision>
      <origin rpy="0 0 0" xyz="0 0 0"/>
      <geometry>
        <mesh filename="package://meshes/kuka/iiwa_link_2.stl"/>
      </geometry>
      <material name="Orange"/>
    </collision>
  </link>
  <!-- joint between link2 and link3 -->
  <joint name="A3" type="revolute">
    <origin rpy="1.5707963267948948 -4.371139000186238E-8 1.5707963705062866" xyz="0.20450 0.00000 0.00000"/>
    <parent link="L2"/>
    <child link="L3"/>
    <axis xyz="0 0 1"/>
    <limit effort="176" lower="-2.96706" upper="2.96706" velocity="1.74533"/>
    <!-- <safety_controller soft_lower_limit="${-168 * PI / 180}"
                          soft_upper_limit="${168 * PI / 180}"
                          k_position="${safety_controller_k_pos}"
                          k_velocity="${safety_controller_k_vel}"/> 
      <dynamics damping="${joint_damping}"/> -->
  </joint>
  <!-- LINK 3-->
  <link name="L3">
    <inertial>
      <origin rpy="0 0 0" xyz="0 0.03 0.13"/>
      <mass value="2.45520"/>
      <inertia ixx="0.00223" ixy="-0.00005" ixz="0.00007" iyy="0.00219" iyz="0.00007" izz="0.00073"/>
    </inertial>
    <visual>
      <origin rpy="0 0 0" xyz="0 0 0"/>
      <geometry>
        <mesh filename="package://meshes/kuka/iiwa_link_3.stl"/>
      </geometry>
      <material name="Orange"/>
    </visual>
    <collision>
      <origin rpy="0 0 0" xyz="0 0 0"/>
      <geometry>
        <mesh filename="package://meshes/kuka/iiwa_link_3.stl"/>
      </geometry>
      <material name="Orange"/>
    </collision>
  </link>
  <!-- joint between link3 and link4 -->
  <joint name="A4" type="revolute">
    <origin rpy="1.5707963705062866 -0.0 0.0" xyz="0.00000 0.00000 0.21550"/>
    <parent link="L3"/>
    <child link="L4"/>
    <axis xyz="0 0 1"/>
    <limit effort="176" lower="-2.0944" upper="2.0944" velocity="1.309"/>
    <!-- <safety_controller soft_lower_limit="${-118 * PI / 180}"
                          soft_upper_limit="${118 * PI / 180}"
                          k_position="${safety_controller_k_pos}"
                          k_velocity="${safety_controller_k_vel}"/> 
      <dynamics damping="${joint_damping}"/> -->
  </joint>
  <!-- LINK 4-->
  <link name="L4">
    <inertial>
      <origin rpy="0 0 0" xyz="0 0.067 0.034"/>
      <mass value="2.61155"/>
      <inertia ixx="0.03844" ixy="0.00088" ixz="-0.00112" iyy="0.01144" iyz="-0.00111" izz="0.04958"/>
    </inertial>
    <visual>
      <origin rpy="0 0 0" xyz="0 0 0"/>
      <geometry>
        <mesh filename="package://meshes/kuka/iiwa_link_4.stl"/>
      </geometry>
      <material name="Orange"/>
    </visual>
    <collision>
      <origin rpy="0 0 0" xyz="0 0 0"/>
      <geometry>
        <mesh filename="package://meshes/kuka/iiwa_link_4.stl"/>
      </geometry>
      <material name="Orange"/>
    </collision>
  </link>
  <!-- joint between link4 and link5 -->
  <joint name="A5" type="revolute">
    <origin rpy="-1.5707963705062866 0.0 -0.0" xyz="0.00000 0.18450 0.00000"/>
    <parent link="L4"/>
    <child link="L5"/>
    <axis xyz="0 0 1"/>
    <limit effort="110" lower="-2.96706" upper="2.96706" velocity="2.26893"/>
    <!-- <safety_controller soft_lower_limit="${-168 * PI / 180}"
                          soft_upper_limit="${168 * PI / 180}"
                          k_position="${safety_controller_k_pos}"
                          k_velocity="${safety_controller_k_vel}"/> 
      <dynamics damping="${joint_damping}"/> -->
  </joint>
  <!-- LINK 5-->
  <link name="L5">
    <inertial>
      <origin rpy="0 0 0" xyz="0.0001 0.021 0.076"/>
      <mass value="3.41000"/>
      <inertia ixx="0.00277" ixy="-0.00001" ixz="0.00001" iyy="0.00284" iyz="0" izz="0.00012"/>
    </inertial>
    <visual>
      <origin rpy="0 0 0" xyz="0 0 0"/>
      <geometry>
        <mesh filename="package://meshes/kuka/iiwa_link_5.stl"/>
      </geometry>
      <material name="Orange"/>
    </visual>
    <collision>
      <origin rpy="0 0 0" xyz="0 0 0"/>
      <geometry>
        <mesh filename="package://meshes/kuka/iiwa_link_5.stl"/>
      </geometry>
      <material name="Orange"/>
    </collision>
  </link>
  <!-- joint between link5 and link6 -->
  <joint name="A6" type="revolute">
    <origin rpy="2.3561944901923457 -1.5707962635746238 2.3561944901923457" xyz="0.00000 -0.06070 0.21550"/>
    <parent link="L5"/>
    <child link="L6"/>
    <axis xyz="0 0 1"/>
    <limit effort="40" lower="-2.0944" upper="2.0944" velocity="2.35619"/>
    <!-- <safety_controller soft_lower_limit="${-118 * PI / 180}"
                          soft_upper_limit="${118 * PI / 180}"
                          k_position="${safety_controller_k_pos}"
                          k_velocity="${safety_controller_k_vel}"/> 
      <dynamics damping="${joint_damping}"/> -->
  </joint>
  <!-- LINK 6-->
  <link name="L6">
    <inertial>
      <origin rpy="0 0 0" xyz="0 0.0006 0.0004"/>
      <mass value="3.38795"/>
      <inertia ixx="0.00050" ixy="-0.00005" ixz="-0.00003" iyy="0.00281" iyz="-0.00004" izz="0.00232"/>
    </inertial>
    <visual>
      <origin rpy="0 0 0" xyz="0 0 0"/>
      <geometry>
        <mesh filename="package://meshes/kuka/iiwa_link_6.stl"/>
      </geometry>
      <material name="Orange"/>
    </visual>
    <collision>
      <origin rpy="0 0 0" xyz="0 0 0"/>
      <geometry>
        <mesh filename="package://meshes/kuka/iiwa_link_6.stl"/>
      </geometry>
      <material name="Orange"/>
    </collision>
  </link>
  <!-- joint between link6 and link7 -->
  <joint name="A7" type="revolute">
    <origin rpy="1.5707963267948948 -4.371139000186238E-8 1.5707963705062866" xyz="0.08100 0.00000 0.06070"/>
    <parent link="L6"/>
    <child link="L7"/>
    <axis xyz="0 0 1"/>
    <limit effort="40" lower="-3.05433" upper="3.05433" velocity="2.35619"/>
    <!-- <safety_controller soft_lower_limit="${-173 * PI / 180}"
                          soft_upper_limit="${173 * PI / 180}"
                          k_position="${safety_controller_k_pos}"
                          k_velocity="${safety_controller_k_vel}"/> 
      <dynamics damping="${joint_damping}"/> -->
  </joint>
  <!-- LINK 7-->
  <link name="L7">
    <inertial>
      <origin rpy="0 0 0" xyz="0 0 0.02"/>
      <mass value="0.35432"/>
      <inertia ixx="0.00795" ixy="0.00022" ixz="-0.00029" iyy="0.01083" iyz="-0.00029" izz="0.00294"/>
    </inertial>
    <visual>
      <origin rpy="0 0 0" xyz="0 0 0"/>
      <geometry>
        <mesh filename="package://meshes/kuka/iiwa_link_7.stl"/>
      </geometry>
      <material name="Grey"/>
    </visual>
    <collision>
      <origin rpy="0 0 0" xyz="0 0 0"/>
      <geometry>
        <mesh filename="package://meshes/kuka/iiwa_link_7.stl"/>
      </geometry>
      <material name="Grey"/>
    </collision>
  </link>
  <!-- kuka_to_ee_joint -->

  <joint name="kuka_to_ee_push_stick_joint" type="fixed">
    <parent link="L7"/>
    <child link="pusher_stick"/>
    <origin rpy="0 0 0" xyz="0 0 0.095"/>
    <limit effort="1000" lower="-10" upper="10" velocity="1000"/>
    <dynamics damping="0.0" friction="0.0"/>
  </joint>

  <joint name="kuka_to_ee_push_tip_joint" type="fixed">
    <parent link="L7"/>
    <child link="pusher_tip"/>
    <origin rpy="0 0 0" xyz="0 0 0.145"/>
    <limit effort="1000" lower="-10" upper="10" velocity="1000"/>
    <dynamics damping="0.0" friction="0.0"/>
  </joint>




  <link name="pusher_stick">
    <inertial>
      <mass value="0.0"/>
      <inertia ixx="0" ixy="0" ixz="0" iyy="0" iyz="0" izz="0"/>
    </inertial>
    <visual>
      <geometry>
        <cylinder radius="0.02" length="0.1"/>
      </geometry>
      <material name="Green" />
    </visual>

    <collision>

      <geometry>
        <cylinder radius="0.02" length=".1"/>
      </geometry>
      <material name="Green"/>
    </collision>
    </link>

  <link name="pusher_tip">

    <inertial>
      <mass value="0.1"/>
      <inertia ixx="0" ixy="0" ixz="0" iyy="0" iyz="0" izz="0"/>
    </inertial>
    <visual>
      <geometry>
        <sphere radius="0.01" />
      </geometry>
      <material name="Red"/>
    </visual>

    <collision>
      <geometry>
        <sphere radius="0.01"/>
      </geometry>
      <material name="Red"/>
    </collision>

  </link>

</robot>