<mujoco model="trifinger_with_ground">
  <compiler angle="radian" autolimits="true" meshdir="meshes"/>
  <size/>
  <default/>

  <asset>
    <!-- Mesh definitions -->
    <mesh name="base_back" file="base_back.stl"/>
    <mesh name="base_front" file="base_front.stl"/>
    <mesh name="base_side_left" file="base_side_left.stl"/>
    <mesh name="base_top" file="base_top.stl"/>
    <mesh name="upper_link" file="upper_link.stl"/>
    <mesh name="middle_link" file="middle_link.stl"/>
    <mesh name="lower_link" file="lower_link.stl"/>

    <!-- Ground texture and material -->
    <texture type="2d" name="groundplane" builtin="checker" mark="edge"
             rgb1="0.2 0.3 0.4" rgb2="0.1 0.2 0.3"
             markrgb="0.8 0.8 0.8"
             width="300" height="300"/>
    <material name="groundplane" texture="groundplane" texuniform="true" texrepeat="5 5" reflectance="0.2"/>
  </asset>

  <worldbody>
    <!-- Ground plane: keep collision enabled (no contype/conaffinity) -->
    <geom name="floor" type="plane" pos="0 0 0" size="1 1 0.1" material="groundplane"/>

    <!-- Base body -->
    <body name="base" pos="0 0 0.0">
      <body name="trifinger_base_link" pos="0 0 0" quat="0.7071068 0 0 -0.7071068">

        <!-- Finger 0 -->
        <body name="finger0_base_link" pos="-0.0455 0.0 0">
          <!-- Disable collision for base geoms -->
          <geom pos="-0.0395 0 0.45" type="mesh" rgba="1 1 1 1" mesh="base_top" contype="0" conaffinity="0"/>
          <geom pos="-0.24495 0 0.37" type="mesh" rgba="1 1 1 1" mesh="base_back" contype="0" conaffinity="0"/>
          <geom pos="-0.0395 0 0.37" type="mesh" rgba="1 1 1 1" mesh="base_front" contype="0" conaffinity="0"/>
          <geom pos="-0.0395 0.02 0.45" type="mesh" rgba="1 1 1 1" mesh="base_side_left" contype="0" conaffinity="0"/>

          <body name="finger0_upper_link" pos="-0.065 0 0.37">
            <inertial pos="-0.079 0 0" quat="0.531109 0.531109 0.466822 0.466822"
                      mass="0.14854" diaginertia="0.000416469 0.00041 2.35312e-05"/>
            <joint name="finger0_base_to_upper_joint" pos="0 0 0" axis="-1 0 0" range="-1.5708 1.5708"/>
            <!-- Disable collision for upper link -->
            <geom name="finger0_upper_link" pos="0.0195 0 0" type="mesh" mesh="upper_link" rgba="0.6 0.0 0.0 1" contype="0" conaffinity="0"/>

            <body name="finger0_middle_link" pos="0 -0.014 0">
              <inertial pos="0 -0.019 -0.079" quat="0.705644 0.0454575 -0.0454575 0.705644"
                        mass="0.14854" diaginertia="0.000416469 0.00041 2.35312e-05"/>
              <joint name="finger0_upper_to_middle_joint" pos="0 0 0" axis="0 1 0" range="-1.5708 1.5708"/>
              <!-- Disable collision for middle link -->
              <geom name="finger0_middle_link" type="mesh" mesh="middle_link" rgba="0.6 0.0 0.0 1" contype="0" conaffinity="0"/>

              <body name="finger0_lower_link" pos="0 -0.03745 -0.16">
                <inertial pos="0 -0.0087543 -0.106445" quat="0.999999 0.00169458 0 0"
                          mass="0.0407" diaginertia="0.000158198 0.000158193 1.72395e-07"/>
                <joint name="finger0_middle_to_lower_joint" pos="0 0 0" axis="0 1 0"
                       range="-3.14159 3.14159"/>
                <!-- Keep collision enabled for lower link (no contype/conaffinity) -->
                <geom name="finger0_lower_link" type="mesh" mesh="lower_link" rgba="0.6 0.0 0.0 1" friction="0.8"/>

                <!-- Tip link -->
                <body name="finger0_tip_link" pos="0 -0.008 -0.16">
                  <inertial pos="0 0 0" mass="0.01" diaginertia="1e-6 1e-6 1e-6"/>
                  <!-- No visuals or collisions -->
                </body>

              </body>
            </body>
          </body>
        </body>

        <!-- Finger 1 -->
        <body name="finger1_base_link" pos="0.02275 0.03940416 0" quat="0.5 0 0 -0.8660254">
          <!-- Disable collision for base geoms -->
          <geom pos="-0.0395 0 0.45" type="mesh" mesh="base_top" rgba="0.0 0.6 0.0 1" contype="0" conaffinity="0"/>
          <geom pos="-0.24495 0 0.37" type="mesh" mesh="base_back" rgba="0.0 0.6 0.0 1" contype="0" conaffinity="0"/>
          <geom pos="-0.0395 0 0.37" type="mesh" mesh="base_front" rgba="0.0 0.6 0.0 1" contype="0" conaffinity="0"/>
          <geom pos="-0.0395 0.02 0.45" type="mesh" mesh="base_side_left" rgba="0.0 0.6 0.0 1" contype="0" conaffinity="0"/>

          <body name="finger1_upper_link" pos="-0.065 0 0.37">
            <inertial pos="-0.079 0 0" quat="0.531109 0.531109 0.466822 0.466822"
                      mass="0.14854" diaginertia="0.000416469 0.00041 2.35312e-05"/>
            <joint name="finger1_base_to_upper_joint" pos="0 0 0" axis="-1 0 0"
                   range="-1.5708 1.5708"/>
            <!-- Disable collision for upper link -->
            <geom name="finger1_upper_link" pos="0.0195 0 0" type="mesh" mesh="upper_link"
                  rgba="0.0 0.6 0.0 1" contype="0" conaffinity="0"/>

            <body name="finger1_middle_link" pos="0 -0.014 0">
              <inertial pos="0 -0.019 -0.079" quat="0.705644 0.0454575 -0.0454575 0.705644"
                        mass="0.14854" diaginertia="0.000416469 0.00041 2.35312e-05"/>
              <joint name="finger1_upper_to_middle_joint" pos="0 0 0" axis="0 1 0"
                     range="-1.5708 1.5708"/>
              <!-- Disable collision for middle link -->
              <geom name="finger1_middle_link" type="mesh" mesh="middle_link"
                    rgba="0.0 0.6 0.0 1" contype="0" conaffinity="0"/>

              <body name="finger1_lower_link" pos="0 -0.03745 -0.16">
                <inertial pos="0 -0.0087543 -0.106445" quat="0.999999 0.00169458 0 0"
                          mass="0.0407" diaginertia="0.000158198 0.000158193 1.72395e-07"/>
                <joint name="finger1_middle_to_lower_joint" pos="0 0 0" axis="0 1 0"
                       range="-3.14159 3.14159"/>
                <!-- Keep collision enabled for lower link -->
                <geom name="finger1_lower_link" type="mesh" mesh="lower_link"
                      rgba="0.0 0.6 0.0 1" friction="0.8"/>

                <!-- Tip link -->
                <body name="finger1_tip_link" pos="0 -0.008 -0.16">
                  <inertial pos="0 0 0" mass="0.01" diaginertia="1e-6 1e-6 1e-6"/>
                  <!-- No visuals or collisions -->
                </body>

              </body>
            </body>
          </body>
        </body>

        <!-- Finger 2 -->
        <body name="finger2_base_link" pos="0.02275 -0.03940416 0" quat="0.5 0 0 0.8660254">
          <!-- Disable collision for base geoms -->
          <geom pos="-0.0395 0 0.45" type="mesh" mesh="base_top" rgba="0.0 0.0 0.6 1" contype="0" conaffinity="0"/>
          <geom pos="-0.24495 0 0.37" type="mesh" mesh="base_back" rgba="0.0 0.0 0.6 1" contype="0" conaffinity="0"/>
          <geom pos="-0.0395 0 0.37" type="mesh" mesh="base_front" rgba="0.0 0.0 0.6 1" contype="0" conaffinity="0"/>
          <geom pos="-0.0395 0.02 0.45" type="mesh" mesh="base_side_left" rgba="0.0 0.0 0.6 1" contype="0" conaffinity="0"/>

          <body name="finger2_upper_link" pos="-0.065 0 0.37">
            <inertial pos="-0.079 0 0" quat="0.531109 0.531109 0.466822 0.466822"
                      mass="0.14854" diaginertia="0.000416469 0.00041 2.35312e-05"/>
            <joint name="finger2_base_to_upper_joint" pos="0 0 0" axis="-1 0 0"
                   range="-1.5708 1.5708"/>
            <!-- Disable collision for upper link -->
            <geom name="finger2_upper_link" pos="0.0195 0 0" type="mesh" mesh="upper_link"
                  rgba="0.0 0.0 0.6 1" contype="0" conaffinity="0"/>

            <body name="finger2_middle_link" pos="0 -0.014 0">
              <inertial pos="0 -0.019 -0.079" quat="0.705644 0.0454575 -0.0454575 0.705644"
                        mass="0.14854" diaginertia="0.000416469 0.00041 2.35312e-05"/>
              <joint name="finger2_upper_to_middle_joint" pos="0 0 0" axis="0 1 0"
                     range="-1.5708 1.5708"/>
              <!-- Disable collision for middle link -->
              <geom name="finger2_middle_link" type="mesh" mesh="middle_link"
                    rgba="0.0 0.0 0.6 1" contype="0" conaffinity="0"/>

              <body name="finger2_lower_link" pos="0 -0.03745 -0.16">
                <inertial pos="0 -0.0087543 -0.106445" quat="0.999999 0.00169458 0 0"
                          mass="0.0407" diaginertia="0.000158198 0.000158193 1.72395e-07"/>
                <joint name="finger2_middle_to_lower_joint" pos="0 0 0" axis="0 1 0"
                       range="-3.14159 3.14159"/>
                <!-- Keep collision enabled for lower link -->
                <geom name="finger2_lower_link" type="mesh" mesh="lower_link"
                      rgba="0.0 0.0 0.6 1" friction="0.8"/>

                <!-- Tip link -->
                <body name="finger2_tip_link" pos="0 -0.008 -0.16">
                  <inertial pos="0 0 0" mass="0.01" diaginertia="1e-6 1e-6 1e-6"/>
                  <!-- No visuals or collisions -->
                </body>

              </body>
            </body>
          </body>
        </body>
      </body> <!-- trifinger_base_link -->
    </body> <!-- base -->
  </worldbody>

  <actuator>
    <!-- Actuators for finger0 -->
    <motor name="finger0_base_to_upper_joint_act" gear="1" joint="finger0_base_to_upper_joint"/>
    <motor name="finger0_upper_to_middle_joint_act" gear="1" joint="finger0_upper_to_middle_joint"/>
    <motor name="finger0_middle_to_lower_joint_act" gear="1" joint="finger0_middle_to_lower_joint"/>
    <!-- Actuators for finger1 -->
    <motor name="finger1_base_to_upper_joint_act" gear="1" joint="finger1_base_to_upper_joint"/>
    <motor name="finger1_upper_to_middle_joint_act" gear="1" joint="finger1_upper_to_middle_joint"/>
    <motor name="finger1_middle_to_lower_joint_act" gear="1" joint="finger1_middle_to_lower_joint"/>
    <!-- Actuators for finger2 -->
    <motor name="finger2_base_to_upper_joint_act" gear="1" joint="finger2_base_to_upper_joint"/>
    <motor name="finger2_upper_to_middle_joint_act" gear="1" joint="finger2_upper_to_middle_joint"/>
    <motor name="finger2_middle_to_lower_joint_act" gear="1" joint="finger2_middle_to_lower_joint"/>
  </actuator>
</mujoco>
